Not Found: /favicon.ico
Internal Server Error: /item/153/item_info
Traceback (most recent call last):
  File "C:\Users\storm\AppData\Local\Programs\Python\Python38-32\lib\site-packages\django\db\models\query.py", line 554, in update_or_create
    obj = self.select_for_update().get(**kwargs)
  File "C:\Users\storm\AppData\Local\Programs\Python\Python38-32\lib\site-packages\django\db\models\query.py", line 406, in get
    raise self.model.DoesNotExist(
authorization.models.People.DoesNotExist: People matching query does not exist.

During handling of the above exception, another exception occurred:

Traceback (most recent call last):
  File "C:\Users\storm\AppData\Local\Programs\Python\Python38-32\lib\site-packages\django\db\backends\utils.py", line 84, in _execute
    return self.cursor.execute(sql, params)
  File "C:\Users\storm\AppData\Local\Programs\Python\Python38-32\lib\site-packages\django\db\backends\sqlite3\base.py", line 383, in execute
    return Database.Cursor.execute(self, query, params)
sqlite3.OperationalError: database is locked

The above exception was the direct cause of the following exception:

Traceback (most recent call last):
  File "C:\Users\storm\AppData\Local\Programs\Python\Python38-32\lib\site-packages\django\core\handlers\exception.py", line 34, in inner
    response = get_response(request)
  File "C:\Users\storm\AppData\Local\Programs\Python\Python38-32\lib\site-packages\django\core\handlers\base.py", line 115, in _get_response
    response = self.process_exception_by_middleware(e, request)
  File "C:\Users\storm\AppData\Local\Programs\Python\Python38-32\lib\site-packages\django\core\handlers\base.py", line 113, in _get_response
    response = wrapped_callback(request, *callback_args, **callback_kwargs)
  File "C:\Users\storm\AppData\Local\Programs\Python\Python38-32\lib\site-packages\django\views\generic\base.py", line 71, in view
    return self.dispatch(request, *args, **kwargs)
  File "C:\Users\storm\AppData\Local\Programs\Python\Python38-32\lib\site-packages\django\contrib\auth\mixins.py", line 52, in dispatch
    return super().dispatch(request, *args, **kwargs)
  File "C:\Users\storm\AppData\Local\Programs\Python\Python38-32\lib\site-packages\django\views\generic\base.py", line 97, in dispatch
    return handler(request, *args, **kwargs)
  File "C:\Users\storm\AppData\Local\Programs\Python\Python38-32\lib\site-packages\django\views\generic\edit.py", line 194, in post
    return super().post(request, *args, **kwargs)
  File "C:\Users\storm\AppData\Local\Programs\Python\Python38-32\lib\site-packages\django\views\generic\edit.py", line 142, in post
    return self.form_valid(form)
  File "C:\Users\storm\Documents\crm\CRM_Sedicomm\authorization\views.py", line 371, in form_valid
    People.objects.update_or_create(
  File "C:\Users\storm\AppData\Local\Programs\Python\Python38-32\lib\site-packages\django\db\models\manager.py", line 82, in manager_method
    return getattr(self.get_queryset(), name)(*args, **kwargs)
  File "C:\Users\storm\AppData\Local\Programs\Python\Python38-32\lib\site-packages\django\db\models\query.py", line 559, in update_or_create
    obj, created = self._create_object_from_params(kwargs, params, lock=True)
  File "C:\Users\storm\AppData\Local\Programs\Python\Python38-32\lib\site-packages\django\db\models\query.py", line 575, in _create_object_from_params
    obj = self.create(**params)
  File "C:\Users\storm\AppData\Local\Programs\Python\Python38-32\lib\site-packages\django\db\models\query.py", line 422, in create
    obj.save(force_insert=True, using=self.db)
  File "C:\Users\storm\Documents\crm\CRM_Sedicomm\authorization\models.py", line 170, in save
    return super().save(**kwargs)
  File "C:\Users\storm\AppData\Local\Programs\Python\Python38-32\lib\site-packages\django\db\models\base.py", line 740, in save
    self.save_base(using=using, force_insert=force_insert,
  File "C:\Users\storm\AppData\Local\Programs\Python\Python38-32\lib\site-packages\django\db\models\base.py", line 777, in save_base
    updated = self._save_table(
  File "C:\Users\storm\AppData\Local\Programs\Python\Python38-32\lib\site-packages\django\db\models\base.py", line 870, in _save_table
    result = self._do_insert(cls._base_manager, using, fields, update_pk, raw)
  File "C:\Users\storm\AppData\Local\Programs\Python\Python38-32\lib\site-packages\django\db\models\base.py", line 907, in _do_insert
    return manager._insert([self], fields=fields, return_id=update_pk,
  File "C:\Users\storm\AppData\Local\Programs\Python\Python38-32\lib\site-packages\django\db\models\manager.py", line 82, in manager_method
    return getattr(self.get_queryset(), name)(*args, **kwargs)
  File "C:\Users\storm\AppData\Local\Programs\Python\Python38-32\lib\site-packages\django\db\models\query.py", line 1186, in _insert
    return query.get_compiler(using=using).execute_sql(return_id)
  File "C:\Users\storm\AppData\Local\Programs\Python\Python38-32\lib\site-packages\django\db\models\sql\compiler.py", line 1335, in execute_sql
    cursor.execute(sql, params)
  File "C:\Users\storm\AppData\Local\Programs\Python\Python38-32\lib\site-packages\django\db\backends\utils.py", line 99, in execute
    return super().execute(sql, params)
  File "C:\Users\storm\AppData\Local\Programs\Python\Python38-32\lib\site-packages\django\db\backends\utils.py", line 67, in execute
    return self._execute_with_wrappers(sql, params, many=False, executor=self._execute)
  File "C:\Users\storm\AppData\Local\Programs\Python\Python38-32\lib\site-packages\django\db\backends\utils.py", line 76, in _execute_with_wrappers
    return executor(sql, params, many, context)
  File "C:\Users\storm\AppData\Local\Programs\Python\Python38-32\lib\site-packages\django\db\backends\utils.py", line 84, in _execute
    return self.cursor.execute(sql, params)
  File "C:\Users\storm\AppData\Local\Programs\Python\Python38-32\lib\site-packages\django\db\utils.py", line 89, in __exit__
    raise dj_exc_value.with_traceback(traceback) from exc_value
  File "C:\Users\storm\AppData\Local\Programs\Python\Python38-32\lib\site-packages\django\db\backends\utils.py", line 84, in _execute
    return self.cursor.execute(sql, params)
  File "C:\Users\storm\AppData\Local\Programs\Python\Python38-32\lib\site-packages\django\db\backends\sqlite3\base.py", line 383, in execute
    return Database.Cursor.execute(self, query, params)
django.db.utils.OperationalError: database is locked
Internal Server Error: /item/151/item_info
Traceback (most recent call last):
  File "C:\Users\storm\AppData\Local\Programs\Python\Python38-32\lib\site-packages\django\core\handlers\exception.py", line 34, in inner
    response = get_response(request)
  File "C:\Users\storm\AppData\Local\Programs\Python\Python38-32\lib\site-packages\django\core\handlers\base.py", line 115, in _get_response
    response = self.process_exception_by_middleware(e, request)
  File "C:\Users\storm\AppData\Local\Programs\Python\Python38-32\lib\site-packages\django\core\handlers\base.py", line 113, in _get_response
    response = wrapped_callback(request, *callback_args, **callback_kwargs)
  File "C:\Users\storm\AppData\Local\Programs\Python\Python38-32\lib\site-packages\django\views\generic\base.py", line 71, in view
    return self.dispatch(request, *args, **kwargs)
  File "C:\Users\storm\AppData\Local\Programs\Python\Python38-32\lib\site-packages\django\contrib\auth\mixins.py", line 52, in dispatch
    return super().dispatch(request, *args, **kwargs)
  File "C:\Users\storm\AppData\Local\Programs\Python\Python38-32\lib\site-packages\django\views\generic\base.py", line 97, in dispatch
    return handler(request, *args, **kwargs)
  File "C:\Users\storm\AppData\Local\Programs\Python\Python38-32\lib\site-packages\django\views\generic\edit.py", line 194, in post
    return super().post(request, *args, **kwargs)
  File "C:\Users\storm\AppData\Local\Programs\Python\Python38-32\lib\site-packages\django\views\generic\edit.py", line 142, in post
    return self.form_valid(form)
  File "C:\Users\storm\Documents\crm\CRM_Sedicomm\authorization\views.py", line 397, in form_valid
    print(l)
NameError: name 'l' is not defined
